{"uid":"44b60e3c9b00fde","name":"test_join_community_with_latency","fullName":"tests.test_join_community.TestJoinCommunity#test_join_community_with_latency","historyId":"c03b8c5d33abbf92b5cd45f8a8de165b","time":{"start":1729211654602,"stop":1729211739063,"duration":84461},"status":"broken","statusMessage":"RuntimeError: Request to http://127.0.0.1:7746 usig method wakuext_fetchCommunity timed out after 10 seconds. Node: first_node","statusTrace":"/opt/hostedtoolcache/Python/3.12.7/x64/lib/python3.12/site-packages/urllib3/connectionpool.py:536: in _make_request\n    response = conn.getresponse()\n/opt/hostedtoolcache/Python/3.12.7/x64/lib/python3.12/site-packages/urllib3/connection.py:461: in getresponse\n    httplib_response = super().getresponse()\n/opt/hostedtoolcache/Python/3.12.7/x64/lib/python3.12/http/client.py:1428: in getresponse\n    response.begin()\n/opt/hostedtoolcache/Python/3.12.7/x64/lib/python3.12/http/client.py:331: in begin\n    version, status, reason = self._read_status()\n/opt/hostedtoolcache/Python/3.12.7/x64/lib/python3.12/http/client.py:292: in _read_status\n    line = str(self.fp.readline(_MAXLINE + 1), \"iso-8859-1\")\n/opt/hostedtoolcache/Python/3.12.7/x64/lib/python3.12/socket.py:720: in readinto\n    return self._sock.recv_into(b)\nE   TimeoutError: timed out\n\nThe above exception was the direct cause of the following exception:\n/opt/hostedtoolcache/Python/3.12.7/x64/lib/python3.12/site-packages/requests/adapters.py:486: in send\n    resp = conn.urlopen(\n/opt/hostedtoolcache/Python/3.12.7/x64/lib/python3.12/site-packages/urllib3/connectionpool.py:844: in urlopen\n    retries = retries.increment(\n/opt/hostedtoolcache/Python/3.12.7/x64/lib/python3.12/site-packages/urllib3/util/retry.py:470: in increment\n    raise reraise(type(error), error, _stacktrace)\n/opt/hostedtoolcache/Python/3.12.7/x64/lib/python3.12/site-packages/urllib3/util/util.py:39: in reraise\n    raise value\n/opt/hostedtoolcache/Python/3.12.7/x64/lib/python3.12/site-packages/urllib3/connectionpool.py:790: in urlopen\n    response = self._make_request(\n/opt/hostedtoolcache/Python/3.12.7/x64/lib/python3.12/site-packages/urllib3/connectionpool.py:538: in _make_request\n    self._raise_timeout(err=e, url=url, timeout_value=read_timeout)\n/opt/hostedtoolcache/Python/3.12.7/x64/lib/python3.12/site-packages/urllib3/connectionpool.py:370: in _raise_timeout\n    raise ReadTimeoutError(\nE   urllib3.exceptions.ReadTimeoutError: HTTPConnectionPool(host='127.0.0.1', port=7746): Read timed out. (read timeout=10)\n\nDuring handling of the above exception, another exception occurred:\nsrc/node/rpc_client.py:24: in send_rpc_request\n    response = requests.post(self.base_url, headers={\"Content-Type\": \"application/json\"}, data=json.dumps(payload), timeout=timeout)\n/opt/hostedtoolcache/Python/3.12.7/x64/lib/python3.12/site-packages/requests/api.py:115: in post\n    return request(\"post\", url, data=data, json=json, **kwargs)\n/opt/hostedtoolcache/Python/3.12.7/x64/lib/python3.12/site-packages/requests/api.py:59: in request\n    return session.request(method=method, url=url, **kwargs)\n/opt/hostedtoolcache/Python/3.12.7/x64/lib/python3.12/site-packages/requests/sessions.py:589: in request\n    resp = self.send(prep, **send_kwargs)\n/opt/hostedtoolcache/Python/3.12.7/x64/lib/python3.12/site-packages/requests/sessions.py:703: in send\n    r = adapter.send(request, **kwargs)\n/opt/hostedtoolcache/Python/3.12.7/x64/lib/python3.12/site-packages/requests/adapters.py:532: in send\n    raise ReadTimeout(e, request=request)\nE   requests.exceptions.ReadTimeout: HTTPConnectionPool(host='127.0.0.1', port=7746): Read timed out. (read timeout=10)\n\nDuring handling of the above exception, another exception occurred:\ntests/test_join_community.py:55: in test_join_community_with_latency\n    self.test_join_community_baseline()\ntests/test_join_community.py:19: in test_join_community_baseline\n    self.first_node.fetch_community(community_id)\n/opt/hostedtoolcache/Python/3.12.7/x64/lib/python3.12/site-packages/tenacity/__init__.py:289: in wrapped_f\n    return self(f, *args, **kw)\n/opt/hostedtoolcache/Python/3.12.7/x64/lib/python3.12/site-packages/tenacity/__init__.py:379: in __call__\n    do = self.iter(retry_state=retry_state)\n/opt/hostedtoolcache/Python/3.12.7/x64/lib/python3.12/site-packages/tenacity/__init__.py:325: in iter\n    raise retry_exc.reraise()\n/opt/hostedtoolcache/Python/3.12.7/x64/lib/python3.12/site-packages/tenacity/__init__.py:158: in reraise\n    raise self.last_attempt.result()\n/opt/hostedtoolcache/Python/3.12.7/x64/lib/python3.12/concurrent/futures/_base.py:449: in result\n    return self.__get_result()\n/opt/hostedtoolcache/Python/3.12.7/x64/lib/python3.12/concurrent/futures/_base.py:401: in __get_result\n    raise self._exception\n/opt/hostedtoolcache/Python/3.12.7/x64/lib/python3.12/site-packages/tenacity/__init__.py:382: in __call__\n    result = fn(*args, **kwargs)\nsrc/node/status_node.py:193: in fetch_community\n    return self.api.send_rpc_request(\"wakuext_fetchCommunity\", params, timeout=10)\n/opt/hostedtoolcache/Python/3.12.7/x64/lib/python3.12/site-packages/tenacity/__init__.py:289: in wrapped_f\n    return self(f, *args, **kw)\n/opt/hostedtoolcache/Python/3.12.7/x64/lib/python3.12/site-packages/tenacity/__init__.py:379: in __call__\n    do = self.iter(retry_state=retry_state)\n/opt/hostedtoolcache/Python/3.12.7/x64/lib/python3.12/site-packages/tenacity/__init__.py:325: in iter\n    raise retry_exc.reraise()\n/opt/hostedtoolcache/Python/3.12.7/x64/lib/python3.12/site-packages/tenacity/__init__.py:158: in reraise\n    raise self.last_attempt.result()\n/opt/hostedtoolcache/Python/3.12.7/x64/lib/python3.12/concurrent/futures/_base.py:449: in result\n    return self.__get_result()\n/opt/hostedtoolcache/Python/3.12.7/x64/lib/python3.12/concurrent/futures/_base.py:401: in __get_result\n    raise self._exception\n/opt/hostedtoolcache/Python/3.12.7/x64/lib/python3.12/site-packages/tenacity/__init__.py:382: in __call__\n    result = fn(*args, **kwargs)\nsrc/node/rpc_client.py:33: in send_rpc_request\n    raise RuntimeError(error_message)\nE   RuntimeError: Request to http://127.0.0.1:7746 usig method wakuext_fetchCommunity timed out after 10 seconds. Node: first_node","flaky":true,"newFailed":false,"newBroken":true,"newPassed":false,"retriesCount":0,"retriesStatusChange":false,"beforeStages":[{"name":"set_allure_env_variables","time":{"start":1729210570371,"stop":1729210570371,"duration":0},"status":"passed","steps":[],"attachments":[],"parameters":[],"shouldDisplayMessage":false,"stepsCount":0,"attachmentsCount":0,"hasContent":false,"attachmentStep":false},{"name":"clear_open_nodes","time":{"start":1729211646890,"stop":1729211646890,"duration":0},"status":"passed","steps":[],"attachments":[],"parameters":[],"shouldDisplayMessage":false,"stepsCount":0,"attachmentsCount":0,"hasContent":false,"attachmentStep":false},{"name":"start_1_node","time":{"start":1729211646890,"stop":1729211654601,"duration":7711},"status":"passed","steps":[],"attachments":[],"parameters":[],"shouldDisplayMessage":false,"stepsCount":0,"attachmentsCount":0,"hasContent":false,"attachmentStep":false},{"name":"save_node_logs_on_fail","time":{"start":1729211646890,"stop":1729211646890,"duration":0},"status":"passed","steps":[],"attachments":[],"parameters":[],"shouldDisplayMessage":false,"stepsCount":0,"attachmentsCount":0,"hasContent":false,"attachmentStep":false}],"testStage":{"status":"broken","statusMessage":"RuntimeError: Request to http://127.0.0.1:7746 usig method wakuext_fetchCommunity timed out after 10 seconds. Node: first_node","statusTrace":"/opt/hostedtoolcache/Python/3.12.7/x64/lib/python3.12/site-packages/urllib3/connectionpool.py:536: in _make_request\n    response = conn.getresponse()\n/opt/hostedtoolcache/Python/3.12.7/x64/lib/python3.12/site-packages/urllib3/connection.py:461: in getresponse\n    httplib_response = super().getresponse()\n/opt/hostedtoolcache/Python/3.12.7/x64/lib/python3.12/http/client.py:1428: in getresponse\n    response.begin()\n/opt/hostedtoolcache/Python/3.12.7/x64/lib/python3.12/http/client.py:331: in begin\n    version, status, reason = self._read_status()\n/opt/hostedtoolcache/Python/3.12.7/x64/lib/python3.12/http/client.py:292: in _read_status\n    line = str(self.fp.readline(_MAXLINE + 1), \"iso-8859-1\")\n/opt/hostedtoolcache/Python/3.12.7/x64/lib/python3.12/socket.py:720: in readinto\n    return self._sock.recv_into(b)\nE   TimeoutError: timed out\n\nThe above exception was the direct cause of the following exception:\n/opt/hostedtoolcache/Python/3.12.7/x64/lib/python3.12/site-packages/requests/adapters.py:486: in send\n    resp = conn.urlopen(\n/opt/hostedtoolcache/Python/3.12.7/x64/lib/python3.12/site-packages/urllib3/connectionpool.py:844: in urlopen\n    retries = retries.increment(\n/opt/hostedtoolcache/Python/3.12.7/x64/lib/python3.12/site-packages/urllib3/util/retry.py:470: in increment\n    raise reraise(type(error), error, _stacktrace)\n/opt/hostedtoolcache/Python/3.12.7/x64/lib/python3.12/site-packages/urllib3/util/util.py:39: in reraise\n    raise value\n/opt/hostedtoolcache/Python/3.12.7/x64/lib/python3.12/site-packages/urllib3/connectionpool.py:790: in urlopen\n    response = self._make_request(\n/opt/hostedtoolcache/Python/3.12.7/x64/lib/python3.12/site-packages/urllib3/connectionpool.py:538: in _make_request\n    self._raise_timeout(err=e, url=url, timeout_value=read_timeout)\n/opt/hostedtoolcache/Python/3.12.7/x64/lib/python3.12/site-packages/urllib3/connectionpool.py:370: in _raise_timeout\n    raise ReadTimeoutError(\nE   urllib3.exceptions.ReadTimeoutError: HTTPConnectionPool(host='127.0.0.1', port=7746): Read timed out. (read timeout=10)\n\nDuring handling of the above exception, another exception occurred:\nsrc/node/rpc_client.py:24: in send_rpc_request\n    response = requests.post(self.base_url, headers={\"Content-Type\": \"application/json\"}, data=json.dumps(payload), timeout=timeout)\n/opt/hostedtoolcache/Python/3.12.7/x64/lib/python3.12/site-packages/requests/api.py:115: in post\n    return request(\"post\", url, data=data, json=json, **kwargs)\n/opt/hostedtoolcache/Python/3.12.7/x64/lib/python3.12/site-packages/requests/api.py:59: in request\n    return session.request(method=method, url=url, **kwargs)\n/opt/hostedtoolcache/Python/3.12.7/x64/lib/python3.12/site-packages/requests/sessions.py:589: in request\n    resp = self.send(prep, **send_kwargs)\n/opt/hostedtoolcache/Python/3.12.7/x64/lib/python3.12/site-packages/requests/sessions.py:703: in send\n    r = adapter.send(request, **kwargs)\n/opt/hostedtoolcache/Python/3.12.7/x64/lib/python3.12/site-packages/requests/adapters.py:532: in send\n    raise ReadTimeout(e, request=request)\nE   requests.exceptions.ReadTimeout: HTTPConnectionPool(host='127.0.0.1', port=7746): Read timed out. (read timeout=10)\n\nDuring handling of the above exception, another exception occurred:\ntests/test_join_community.py:55: in test_join_community_with_latency\n    self.test_join_community_baseline()\ntests/test_join_community.py:19: in test_join_community_baseline\n    self.first_node.fetch_community(community_id)\n/opt/hostedtoolcache/Python/3.12.7/x64/lib/python3.12/site-packages/tenacity/__init__.py:289: in wrapped_f\n    return self(f, *args, **kw)\n/opt/hostedtoolcache/Python/3.12.7/x64/lib/python3.12/site-packages/tenacity/__init__.py:379: in __call__\n    do = self.iter(retry_state=retry_state)\n/opt/hostedtoolcache/Python/3.12.7/x64/lib/python3.12/site-packages/tenacity/__init__.py:325: in iter\n    raise retry_exc.reraise()\n/opt/hostedtoolcache/Python/3.12.7/x64/lib/python3.12/site-packages/tenacity/__init__.py:158: in reraise\n    raise self.last_attempt.result()\n/opt/hostedtoolcache/Python/3.12.7/x64/lib/python3.12/concurrent/futures/_base.py:449: in result\n    return self.__get_result()\n/opt/hostedtoolcache/Python/3.12.7/x64/lib/python3.12/concurrent/futures/_base.py:401: in __get_result\n    raise self._exception\n/opt/hostedtoolcache/Python/3.12.7/x64/lib/python3.12/site-packages/tenacity/__init__.py:382: in __call__\n    result = fn(*args, **kwargs)\nsrc/node/status_node.py:193: in fetch_community\n    return self.api.send_rpc_request(\"wakuext_fetchCommunity\", params, timeout=10)\n/opt/hostedtoolcache/Python/3.12.7/x64/lib/python3.12/site-packages/tenacity/__init__.py:289: in wrapped_f\n    return self(f, *args, **kw)\n/opt/hostedtoolcache/Python/3.12.7/x64/lib/python3.12/site-packages/tenacity/__init__.py:379: in __call__\n    do = self.iter(retry_state=retry_state)\n/opt/hostedtoolcache/Python/3.12.7/x64/lib/python3.12/site-packages/tenacity/__init__.py:325: in iter\n    raise retry_exc.reraise()\n/opt/hostedtoolcache/Python/3.12.7/x64/lib/python3.12/site-packages/tenacity/__init__.py:158: in reraise\n    raise self.last_attempt.result()\n/opt/hostedtoolcache/Python/3.12.7/x64/lib/python3.12/concurrent/futures/_base.py:449: in result\n    return self.__get_result()\n/opt/hostedtoolcache/Python/3.12.7/x64/lib/python3.12/concurrent/futures/_base.py:401: in __get_result\n    raise self._exception\n/opt/hostedtoolcache/Python/3.12.7/x64/lib/python3.12/site-packages/tenacity/__init__.py:382: in __call__\n    result = fn(*args, **kwargs)\nsrc/node/rpc_client.py:33: in send_rpc_request\n    raise RuntimeError(error_message)\nE   RuntimeError: Request to http://127.0.0.1:7746 usig method wakuext_fetchCommunity timed out after 10 seconds. Node: first_node","steps":[],"attachments":[{"uid":"fc02ded395cd69d3","name":"log","source":"fc02ded395cd69d3.txt","type":"text/plain","size":118287}],"parameters":[],"shouldDisplayMessage":true,"stepsCount":0,"attachmentsCount":1,"hasContent":true,"attachmentStep":false},"afterStages":[{"name":"save_node_logs_on_fail::0","time":{"start":1729211739278,"stop":1729211739280,"duration":2},"status":"passed","steps":[],"attachments":[],"parameters":[],"shouldDisplayMessage":false,"stepsCount":0,"attachmentsCount":0,"hasContent":false,"attachmentStep":false},{"name":"clear_open_nodes::0","time":{"start":1729211739280,"stop":1729211739487,"duration":207},"status":"passed","steps":[],"attachments":[],"parameters":[],"shouldDisplayMessage":false,"stepsCount":0,"attachmentsCount":0,"hasContent":false,"attachmentStep":false},{"name":"set_allure_env_variables::0","time":{"start":1729212418448,"stop":1729212418448,"duration":0},"status":"passed","steps":[],"attachments":[],"parameters":[],"shouldDisplayMessage":false,"stepsCount":0,"attachmentsCount":0,"hasContent":false,"attachmentStep":false}],"labels":[{"name":"tag","value":"@pytest.mark.usefixtures('start_1_node')"},{"name":"parentSuite","value":"tests"},{"name":"suite","value":"test_join_community"},{"name":"subSuite","value":"TestJoinCommunity"},{"name":"host","value":"fv-az1535-618"},{"name":"thread","value":"76809-MainThread"},{"name":"framework","value":"pytest"},{"name":"language","value":"cpython3"},{"name":"package","value":"tests.test_join_community"},{"name":"resultFormat","value":"allure2"}],"parameters":[],"links":[],"hidden":false,"retry":false,"extra":{"severity":"normal","retries":[],"categories":[{"name":"Test defects","matchedStatuses":[],"flaky":false}],"history":{"statistic":{"failed":5,"broken":2,"skipped":0,"passed":2,"unknown":0,"total":9},"items":[{"uid":"9519628a56a891ec","reportUrl":"https://status-im.github.io/status-cli-tests/246//#testresult/9519628a56a891ec","status":"failed","statusDetails":"AssertionError: Response does not contain 'result' key.","time":{"start":1729125159950,"stop":1729125238557,"duration":78607}},{"uid":"2292fcd344eb21db","reportUrl":"https://status-im.github.io/status-cli-tests/245//#testresult/2292fcd344eb21db","status":"broken","statusDetails":"RuntimeError: Request to http://127.0.0.1:45931 usig method wakuext_fetchCommunity timed out after 10 seconds. Node: first_node","time":{"start":1729068164149,"stop":1729068218577,"duration":54428}},{"uid":"cb50871aa9dc5d82","reportUrl":"https://status-im.github.io/status-cli-tests/244//#testresult/cb50871aa9dc5d82","status":"failed","statusDetails":"AssertionError: Response does not contain 'result' key.","time":{"start":1729039154167,"stop":1729039234652,"duration":80485}},{"uid":"8076c9109b6652d5","reportUrl":"https://status-im.github.io/status-cli-tests/243//#testresult/8076c9109b6652d5","status":"passed","time":{"start":1729006436002,"stop":1729006518289,"duration":82287}},{"uid":"36728de258a302","reportUrl":"https://status-im.github.io/status-cli-tests/242//#testresult/36728de258a302","status":"failed","statusDetails":"AssertionError: Response does not contain 'result' key.","time":{"start":1729003787217,"stop":1729003865932,"duration":78715}},{"uid":"1f0120c34da68e63","reportUrl":"https://status-im.github.io/status-cli-tests/241//#testresult/1f0120c34da68e63","status":"failed","statusDetails":"AssertionError: Response does not contain 'result' key.","time":{"start":1728990151427,"stop":1728990225221,"duration":73794}},{"uid":"117097c361963ac8","reportUrl":"https://status-im.github.io/status-cli-tests/240//#testresult/117097c361963ac8","status":"failed","statusDetails":"AssertionError: Response does not contain 'result' key.","time":{"start":1728952513844,"stop":1728952589078,"duration":75234}},{"uid":"bae2fe3d8e65d5bc","reportUrl":"https://status-im.github.io/status-cli-tests/239//#testresult/bae2fe3d8e65d5bc","status":"passed","time":{"start":1728888959830,"stop":1728889020186,"duration":60356}}]},"tags":["@pytest.mark.usefixtures('start_1_node')"]},"source":"44b60e3c9b00fde.json","parameterValues":[]}