{"uid":"41f8c5a6d60e8c31","name":"test_join_community_baseline","fullName":"tests.test_join_community.TestJoinCommunity#test_join_community_baseline","historyId":"0045b227df045106355999bb08fb6547","time":{"start":1733877620914,"stop":1733877723377,"duration":102463},"status":"broken","statusMessage":"RuntimeError: Request to http://127.0.0.1:53399 usig method wakuext_fetchCommunity timed out after 10 seconds. Node: first_node","statusTrace":"/opt/hostedtoolcache/Python/3.12.7/x64/lib/python3.12/site-packages/urllib3/connectionpool.py:536: in _make_request\n    response = conn.getresponse()\n/opt/hostedtoolcache/Python/3.12.7/x64/lib/python3.12/site-packages/urllib3/connection.py:461: in getresponse\n    httplib_response = super().getresponse()\n/opt/hostedtoolcache/Python/3.12.7/x64/lib/python3.12/http/client.py:1428: in getresponse\n    response.begin()\n/opt/hostedtoolcache/Python/3.12.7/x64/lib/python3.12/http/client.py:331: in begin\n    version, status, reason = self._read_status()\n/opt/hostedtoolcache/Python/3.12.7/x64/lib/python3.12/http/client.py:292: in _read_status\n    line = str(self.fp.readline(_MAXLINE + 1), \"iso-8859-1\")\n/opt/hostedtoolcache/Python/3.12.7/x64/lib/python3.12/socket.py:720: in readinto\n    return self._sock.recv_into(b)\nE   TimeoutError: timed out\n\nThe above exception was the direct cause of the following exception:\n/opt/hostedtoolcache/Python/3.12.7/x64/lib/python3.12/site-packages/requests/adapters.py:486: in send\n    resp = conn.urlopen(\n/opt/hostedtoolcache/Python/3.12.7/x64/lib/python3.12/site-packages/urllib3/connectionpool.py:844: in urlopen\n    retries = retries.increment(\n/opt/hostedtoolcache/Python/3.12.7/x64/lib/python3.12/site-packages/urllib3/util/retry.py:470: in increment\n    raise reraise(type(error), error, _stacktrace)\n/opt/hostedtoolcache/Python/3.12.7/x64/lib/python3.12/site-packages/urllib3/util/util.py:39: in reraise\n    raise value\n/opt/hostedtoolcache/Python/3.12.7/x64/lib/python3.12/site-packages/urllib3/connectionpool.py:790: in urlopen\n    response = self._make_request(\n/opt/hostedtoolcache/Python/3.12.7/x64/lib/python3.12/site-packages/urllib3/connectionpool.py:538: in _make_request\n    self._raise_timeout(err=e, url=url, timeout_value=read_timeout)\n/opt/hostedtoolcache/Python/3.12.7/x64/lib/python3.12/site-packages/urllib3/connectionpool.py:370: in _raise_timeout\n    raise ReadTimeoutError(\nE   urllib3.exceptions.ReadTimeoutError: HTTPConnectionPool(host='127.0.0.1', port=53399): Read timed out. (read timeout=10)\n\nDuring handling of the above exception, another exception occurred:\nsrc/node/rpc_client.py:24: in send_rpc_request\n    response = requests.post(self.base_url, headers={\"Content-Type\": \"application/json\"}, data=json.dumps(payload), timeout=timeout)\n/opt/hostedtoolcache/Python/3.12.7/x64/lib/python3.12/site-packages/requests/api.py:115: in post\n    return request(\"post\", url, data=data, json=json, **kwargs)\n/opt/hostedtoolcache/Python/3.12.7/x64/lib/python3.12/site-packages/requests/api.py:59: in request\n    return session.request(method=method, url=url, **kwargs)\n/opt/hostedtoolcache/Python/3.12.7/x64/lib/python3.12/site-packages/requests/sessions.py:589: in request\n    resp = self.send(prep, **send_kwargs)\n/opt/hostedtoolcache/Python/3.12.7/x64/lib/python3.12/site-packages/requests/sessions.py:703: in send\n    r = adapter.send(request, **kwargs)\n/opt/hostedtoolcache/Python/3.12.7/x64/lib/python3.12/site-packages/requests/adapters.py:532: in send\n    raise ReadTimeout(e, request=request)\nE   requests.exceptions.ReadTimeout: HTTPConnectionPool(host='127.0.0.1', port=53399): Read timed out. (read timeout=10)\n\nDuring handling of the above exception, another exception occurred:\ntests/test_join_community.py:19: in test_join_community_baseline\n    self.first_node.fetch_community(community_id)\n/opt/hostedtoolcache/Python/3.12.7/x64/lib/python3.12/site-packages/tenacity/__init__.py:289: in wrapped_f\n    return self(f, *args, **kw)\n/opt/hostedtoolcache/Python/3.12.7/x64/lib/python3.12/site-packages/tenacity/__init__.py:379: in __call__\n    do = self.iter(retry_state=retry_state)\n/opt/hostedtoolcache/Python/3.12.7/x64/lib/python3.12/site-packages/tenacity/__init__.py:325: in iter\n    raise retry_exc.reraise()\n/opt/hostedtoolcache/Python/3.12.7/x64/lib/python3.12/site-packages/tenacity/__init__.py:158: in reraise\n    raise self.last_attempt.result()\n/opt/hostedtoolcache/Python/3.12.7/x64/lib/python3.12/concurrent/futures/_base.py:449: in result\n    return self.__get_result()\n/opt/hostedtoolcache/Python/3.12.7/x64/lib/python3.12/concurrent/futures/_base.py:401: in __get_result\n    raise self._exception\n/opt/hostedtoolcache/Python/3.12.7/x64/lib/python3.12/site-packages/tenacity/__init__.py:382: in __call__\n    result = fn(*args, **kwargs)\nsrc/node/status_node.py:193: in fetch_community\n    return self.api.send_rpc_request(\"wakuext_fetchCommunity\", params, timeout=10)\n/opt/hostedtoolcache/Python/3.12.7/x64/lib/python3.12/site-packages/tenacity/__init__.py:289: in wrapped_f\n    return self(f, *args, **kw)\n/opt/hostedtoolcache/Python/3.12.7/x64/lib/python3.12/site-packages/tenacity/__init__.py:379: in __call__\n    do = self.iter(retry_state=retry_state)\n/opt/hostedtoolcache/Python/3.12.7/x64/lib/python3.12/site-packages/tenacity/__init__.py:325: in iter\n    raise retry_exc.reraise()\n/opt/hostedtoolcache/Python/3.12.7/x64/lib/python3.12/site-packages/tenacity/__init__.py:158: in reraise\n    raise self.last_attempt.result()\n/opt/hostedtoolcache/Python/3.12.7/x64/lib/python3.12/concurrent/futures/_base.py:449: in result\n    return self.__get_result()\n/opt/hostedtoolcache/Python/3.12.7/x64/lib/python3.12/concurrent/futures/_base.py:401: in __get_result\n    raise self._exception\n/opt/hostedtoolcache/Python/3.12.7/x64/lib/python3.12/site-packages/tenacity/__init__.py:382: in __call__\n    result = fn(*args, **kwargs)\nsrc/node/rpc_client.py:33: in send_rpc_request\n    raise RuntimeError(error_message)\nE   RuntimeError: Request to http://127.0.0.1:53399 usig method wakuext_fetchCommunity timed out after 10 seconds. Node: first_node","flaky":false,"newFailed":false,"newBroken":false,"newPassed":false,"retriesCount":0,"retriesStatusChange":false,"beforeStages":[{"name":"set_allure_env_variables","time":{"start":1733876225067,"stop":1733876225067,"duration":0},"status":"passed","steps":[],"attachments":[],"parameters":[],"shouldDisplayMessage":false,"stepsCount":0,"attachmentsCount":0,"hasContent":false,"attachmentStep":false},{"name":"clear_open_nodes","time":{"start":1733877613102,"stop":1733877613102,"duration":0},"status":"passed","steps":[],"attachments":[],"parameters":[],"shouldDisplayMessage":false,"stepsCount":0,"attachmentsCount":0,"hasContent":false,"attachmentStep":false},{"name":"save_node_logs_on_fail","time":{"start":1733877613102,"stop":1733877613102,"duration":0},"status":"passed","steps":[],"attachments":[],"parameters":[],"shouldDisplayMessage":false,"stepsCount":0,"attachmentsCount":0,"hasContent":false,"attachmentStep":false},{"name":"start_1_node","time":{"start":1733877613102,"stop":1733877620913,"duration":7811},"status":"passed","steps":[],"attachments":[],"parameters":[],"shouldDisplayMessage":false,"stepsCount":0,"attachmentsCount":0,"hasContent":false,"attachmentStep":false}],"testStage":{"status":"broken","statusMessage":"RuntimeError: Request to http://127.0.0.1:53399 usig method wakuext_fetchCommunity timed out after 10 seconds. Node: first_node","statusTrace":"/opt/hostedtoolcache/Python/3.12.7/x64/lib/python3.12/site-packages/urllib3/connectionpool.py:536: in _make_request\n    response = conn.getresponse()\n/opt/hostedtoolcache/Python/3.12.7/x64/lib/python3.12/site-packages/urllib3/connection.py:461: in getresponse\n    httplib_response = super().getresponse()\n/opt/hostedtoolcache/Python/3.12.7/x64/lib/python3.12/http/client.py:1428: in getresponse\n    response.begin()\n/opt/hostedtoolcache/Python/3.12.7/x64/lib/python3.12/http/client.py:331: in begin\n    version, status, reason = self._read_status()\n/opt/hostedtoolcache/Python/3.12.7/x64/lib/python3.12/http/client.py:292: in _read_status\n    line = str(self.fp.readline(_MAXLINE + 1), \"iso-8859-1\")\n/opt/hostedtoolcache/Python/3.12.7/x64/lib/python3.12/socket.py:720: in readinto\n    return self._sock.recv_into(b)\nE   TimeoutError: timed out\n\nThe above exception was the direct cause of the following exception:\n/opt/hostedtoolcache/Python/3.12.7/x64/lib/python3.12/site-packages/requests/adapters.py:486: in send\n    resp = conn.urlopen(\n/opt/hostedtoolcache/Python/3.12.7/x64/lib/python3.12/site-packages/urllib3/connectionpool.py:844: in urlopen\n    retries = retries.increment(\n/opt/hostedtoolcache/Python/3.12.7/x64/lib/python3.12/site-packages/urllib3/util/retry.py:470: in increment\n    raise reraise(type(error), error, _stacktrace)\n/opt/hostedtoolcache/Python/3.12.7/x64/lib/python3.12/site-packages/urllib3/util/util.py:39: in reraise\n    raise value\n/opt/hostedtoolcache/Python/3.12.7/x64/lib/python3.12/site-packages/urllib3/connectionpool.py:790: in urlopen\n    response = self._make_request(\n/opt/hostedtoolcache/Python/3.12.7/x64/lib/python3.12/site-packages/urllib3/connectionpool.py:538: in _make_request\n    self._raise_timeout(err=e, url=url, timeout_value=read_timeout)\n/opt/hostedtoolcache/Python/3.12.7/x64/lib/python3.12/site-packages/urllib3/connectionpool.py:370: in _raise_timeout\n    raise ReadTimeoutError(\nE   urllib3.exceptions.ReadTimeoutError: HTTPConnectionPool(host='127.0.0.1', port=53399): Read timed out. (read timeout=10)\n\nDuring handling of the above exception, another exception occurred:\nsrc/node/rpc_client.py:24: in send_rpc_request\n    response = requests.post(self.base_url, headers={\"Content-Type\": \"application/json\"}, data=json.dumps(payload), timeout=timeout)\n/opt/hostedtoolcache/Python/3.12.7/x64/lib/python3.12/site-packages/requests/api.py:115: in post\n    return request(\"post\", url, data=data, json=json, **kwargs)\n/opt/hostedtoolcache/Python/3.12.7/x64/lib/python3.12/site-packages/requests/api.py:59: in request\n    return session.request(method=method, url=url, **kwargs)\n/opt/hostedtoolcache/Python/3.12.7/x64/lib/python3.12/site-packages/requests/sessions.py:589: in request\n    resp = self.send(prep, **send_kwargs)\n/opt/hostedtoolcache/Python/3.12.7/x64/lib/python3.12/site-packages/requests/sessions.py:703: in send\n    r = adapter.send(request, **kwargs)\n/opt/hostedtoolcache/Python/3.12.7/x64/lib/python3.12/site-packages/requests/adapters.py:532: in send\n    raise ReadTimeout(e, request=request)\nE   requests.exceptions.ReadTimeout: HTTPConnectionPool(host='127.0.0.1', port=53399): Read timed out. (read timeout=10)\n\nDuring handling of the above exception, another exception occurred:\ntests/test_join_community.py:19: in test_join_community_baseline\n    self.first_node.fetch_community(community_id)\n/opt/hostedtoolcache/Python/3.12.7/x64/lib/python3.12/site-packages/tenacity/__init__.py:289: in wrapped_f\n    return self(f, *args, **kw)\n/opt/hostedtoolcache/Python/3.12.7/x64/lib/python3.12/site-packages/tenacity/__init__.py:379: in __call__\n    do = self.iter(retry_state=retry_state)\n/opt/hostedtoolcache/Python/3.12.7/x64/lib/python3.12/site-packages/tenacity/__init__.py:325: in iter\n    raise retry_exc.reraise()\n/opt/hostedtoolcache/Python/3.12.7/x64/lib/python3.12/site-packages/tenacity/__init__.py:158: in reraise\n    raise self.last_attempt.result()\n/opt/hostedtoolcache/Python/3.12.7/x64/lib/python3.12/concurrent/futures/_base.py:449: in result\n    return self.__get_result()\n/opt/hostedtoolcache/Python/3.12.7/x64/lib/python3.12/concurrent/futures/_base.py:401: in __get_result\n    raise self._exception\n/opt/hostedtoolcache/Python/3.12.7/x64/lib/python3.12/site-packages/tenacity/__init__.py:382: in __call__\n    result = fn(*args, **kwargs)\nsrc/node/status_node.py:193: in fetch_community\n    return self.api.send_rpc_request(\"wakuext_fetchCommunity\", params, timeout=10)\n/opt/hostedtoolcache/Python/3.12.7/x64/lib/python3.12/site-packages/tenacity/__init__.py:289: in wrapped_f\n    return self(f, *args, **kw)\n/opt/hostedtoolcache/Python/3.12.7/x64/lib/python3.12/site-packages/tenacity/__init__.py:379: in __call__\n    do = self.iter(retry_state=retry_state)\n/opt/hostedtoolcache/Python/3.12.7/x64/lib/python3.12/site-packages/tenacity/__init__.py:325: in iter\n    raise retry_exc.reraise()\n/opt/hostedtoolcache/Python/3.12.7/x64/lib/python3.12/site-packages/tenacity/__init__.py:158: in reraise\n    raise self.last_attempt.result()\n/opt/hostedtoolcache/Python/3.12.7/x64/lib/python3.12/concurrent/futures/_base.py:449: in result\n    return self.__get_result()\n/opt/hostedtoolcache/Python/3.12.7/x64/lib/python3.12/concurrent/futures/_base.py:401: in __get_result\n    raise self._exception\n/opt/hostedtoolcache/Python/3.12.7/x64/lib/python3.12/site-packages/tenacity/__init__.py:382: in __call__\n    result = fn(*args, **kwargs)\nsrc/node/rpc_client.py:33: in send_rpc_request\n    raise RuntimeError(error_message)\nE   RuntimeError: Request to http://127.0.0.1:53399 usig method wakuext_fetchCommunity timed out after 10 seconds. Node: first_node","steps":[],"attachments":[{"uid":"2fff5a15806ec510","name":"log","source":"2fff5a15806ec510.txt","type":"text/plain","size":518896}],"parameters":[],"shouldDisplayMessage":true,"stepsCount":0,"attachmentsCount":1,"hasContent":true,"attachmentStep":false},"afterStages":[{"name":"save_node_logs_on_fail::0","time":{"start":1733877723627,"stop":1733877723630,"duration":3},"status":"passed","steps":[],"attachments":[],"parameters":[],"shouldDisplayMessage":false,"stepsCount":0,"attachmentsCount":0,"hasContent":false,"attachmentStep":false},{"name":"clear_open_nodes::0","time":{"start":1733877723630,"stop":1733877723826,"duration":196},"status":"passed","steps":[],"attachments":[],"parameters":[],"shouldDisplayMessage":false,"stepsCount":0,"attachmentsCount":0,"hasContent":false,"attachmentStep":false},{"name":"set_allure_env_variables::0","time":{"start":1733878727292,"stop":1733878727293,"duration":1},"status":"passed","steps":[],"attachments":[],"parameters":[],"shouldDisplayMessage":false,"stepsCount":0,"attachmentsCount":0,"hasContent":false,"attachmentStep":false}],"labels":[{"name":"tag","value":"flaky(reruns=2)"},{"name":"tag","value":"@pytest.mark.usefixtures('start_1_node')"},{"name":"parentSuite","value":"tests"},{"name":"suite","value":"test_join_community"},{"name":"subSuite","value":"TestJoinCommunity"},{"name":"host","value":"fv-az1043-896"},{"name":"thread","value":"60587-MainThread"},{"name":"framework","value":"pytest"},{"name":"language","value":"cpython3"},{"name":"package","value":"tests.test_join_community"},{"name":"resultFormat","value":"allure2"}],"parameters":[],"links":[],"hidden":true,"retry":true,"extra":{"categories":[],"tags":["@pytest.mark.usefixtures('start_1_node')","flaky(reruns=2)"]},"source":"41f8c5a6d60e8c31.json","parameterValues":[]}